Workbook

Sheet TRECHOS_LONGOS
A1: ID da viagem (interno) | B1: Nome do viajante | C1: Setor do viajante | D1: Motivo da viagem | E1: Data da compra | F1: Data da viagem | G1: Diferença entre compra e ida (Dias) | H1: Meio de transporte | I1: Cidade origem | J1: Estado origem | K1: Nome do aeroporto ou rodoviária | L1: Cidade destino | M1: Estado destino | N1: Nome do aeroporto ou rodoviária | O1: Nome da empresa de transporte | P1: Quilometragem | Q1: Cumpriu política? | R1: Motivo do não-cumprimento | S1: Passagem foi cancelada? | T1: Valor da compra (R$) | U1: Valor da compra (Pontos) | V1: Taxas extras (R$) | W1: Valor Reembolso (R$) | X1: Valor Reembolso (Pontos) | Y1: Valor Final (R$) | Z1: Valor Final (Pontos)
A2: 1 | B2: Vania Beneveli | C2: PEDAGÓGICO | D2: FORMAÇÃO | E2: 46013 | F2: 46026 | G2: =if(OR(E2 = "", F2 = ""), "", datedif(E2,F2,"D")) -> 13 | H2: AÉREO | I2: Brasília | J2: DF | K2: BSB | L2: João Pessoa | M2: PB | N2: JPA | O2: LATAM | P2: 1720 | Q2: NÃO | S2: NÃO | T2: 2314.34 | U2: 0 | V2: 0 | W2: =if($S2 = "NÃO", 0, if(and(UPPER($O2) = "GOL", $S2 = "SIM"), $T2+$V2, if(and(UPPER($O2) = "LATAM", $S2 = "SIM"), $T2 + $V2, "----"))) -> 0 | X2: =if($S2 = "NÃO", 0, if(and(UPPER($O2) = "GOL", $S2 = "SIM"), 0.95*($U2), if(and(UPPER($O2) = "LATAM", $S2 = "SIM"), $U2, "----"))) -> 0 | Y2: =if($W2 = "----", "Valor do reembolso?", $T2-$W2+$V2) -> 2314.34 | Z2: =if($X2 = "----", "Valor do reembolso?", $U2-$X2) -> 0
A3: 1 | B3: Vania Beneveli | C3: PEDAGÓGICO | D3: FORMAÇÃO | E3: 46013 | F3: 46029 | G3: =if(OR(E3 = "", F3 = ""), "", datedif(E3,F3,"D")) -> 16 | H3: AÉREO | I3: João Pessoa | J3: PB | K3: JPA | L3: Brasília | M3: DF | N3: BSB | O3: LATAM | P3: 1720 | Q3: SIM | S3: NÃO | T3: 1675.38 | U3: 0 | V3: 0 | W3: =if($S3 = "NÃO", 0, if(and(UPPER($O3) = "GOL", $S3 = "SIM"), $T3+$V3, if(and(UPPER($O3) = "LATAM", $S3 = "SIM"), $T3 + $V3, "----"))) -> 0 | X3: =if($S3 = "NÃO", 0, if(and(UPPER($O3) = "GOL", $S3 = "SIM"), 0.95*($U3), if(and(UPPER($O3) = "LATAM", $S3 = "SIM"), $U3, "----"))) -> 0 | Y3: =if($W3 = "----", "Valor do reembolso?", $T3-$W3+$V3) -> 1675.38 | Z3: =if($X3 = "----", "Valor do reembolso?", $U3-$X3) -> 0
A4: 2 | B4: Simone Cortes | C4: PEDAGÓGICO | D4: FORMAÇÃO | E4: 46013 | F4: 46029 | G4: =if(OR(E4 = "", F4 = ""), "", datedif(E4,F4,"D")) -> 16 | H4: AÉREO | I4: Brasília | J4: DF | K4: BSB | L4: João Pessoa | M4: PB | N4: JPA | O4: LATAM | P4: 1720 | Q4: SIM | S4: NÃO | T4: 1752.77 | U4: 0 | V4: 0 | W4: =if($S4 = "NÃO", 0, if(and(UPPER($O4) = "GOL", $S4 = "SIM"), $T4+$V4, if(and(UPPER($O4) = "LATAM", $S4 = "SIM"), $T4 + $V4, "----"))) -> 0 | X4: =if($S4 = "NÃO", 0, if(and(UPPER($O4) = "GOL", $S4 = "SIM"), 0.95*($U4), if(and(UPPER($O4) = "LATAM", $S4 = "SIM"), $U4, "----"))) -> 0 | Y4: =if($W4 = "----", "Valor do reembolso?", $T4-$W4+$V4) -> 1752.77 | Z4: =if($X4 = "----", "Valor do reembolso?", $U4-$X4) -> 0
A5: 2 | B5: Simone Cortes | C5: PEDAGÓGICO | D5: FORMAÇÃO | E5: 46014 | F5: 46036 | G5: =if(OR(E5 = "", F5 = ""), "", datedif(E5,F5,"D")) -> 22 | H5: AÉREO | I5: João Pessoa | J5: PB | K5: JPA | L5: Brasília | M5: DF | N5: BSB | O5: GOL | P5: 1720 | Q5: SIM | S5: NÃO | T5: 1403.99 | U5: 0 | V5: 0 | W5: =if($S5 = "NÃO", 0, if(and(UPPER($O5) = "GOL", $S5 = "SIM"), $T5+$V5, if(and(UPPER($O5) = "LATAM", $S5 = "SIM"), $T5 + $V5, "----"))) -> 0 | X5: =if($S5 = "NÃO", 0, if(and(UPPER($O5) = "GOL", $S5 = "SIM"), 0.95*($U5), if(and(UPPER($O5) = "LATAM", $S5 = "SIM"), $U5, "----"))) -> 0 | Y5: =if($W5 = "----", "Valor do reembolso?", $T5-$W5+$V5) -> 1403.99 | Z5: =if($X5 = "----", "Valor do reembolso?", $U5-$X5) -> 0
A6: 3 | B6: Alexandre Carvalho | C6: PEDAGÓGICO | D6: FORMAÇÃO | E6: 46013 | F6: 46031 | G6: =if(OR(E6 = "", F6 = ""), "", datedif(E6,F6,"D")) -> 18 | H6: AÉREO | I6: Brasília | J6: DF | K6: BSB | L6: João Pessoa | M6: PB | N6: JPA | O6: LATAM | P6: 1720 | Q6: SIM | S6: NÃO | T6: 1752.77 | U6: 0 | V6: 0 | W6: =if($S6 = "NÃO", 0, if(and(UPPER($O6) = "GOL", $S6 = "SIM"), $T6+$V6, if(and(UPPER($O6) = "LATAM", $S6 = "SIM"), $T6 + $V6, "----"))) -> 0 | X6: =if($S6 = "NÃO", 0, if(and(UPPER($O6) = "GOL", $S6 = "SIM"), 0.95*($U6), if(and(UPPER($O6) = "LATAM", $S6 = "SIM"), $U6, "----"))) -> 0 | Y6: =if($W6 = "----", "Valor do reembolso?", $T6-$W6+$V6) -> 1752.77 | Z6: =if($X6 = "----", "Valor do reembolso?", $U6-$X6) -> 0
A7: 3 | B7: Alexandre Carvalho | C7: PEDAGÓGICO | D7: FORMAÇÃO | E7: 46014 | F7: 46036 | G7: =if(OR(E7 = "", F7 = ""), "", datedif(E7,F7,"D")) -> 22 | H7: AÉREO | I7: João Pessoa | J7: PB | K7: JPA | L7: Brasília | M7: PB | N7: JPA | O7: GOL | P7: 1720 | Q7: SIM | S7: NÃO | T7: 1403.99 | U7: 0 | V7: 0 | W7: =if($S7 = "NÃO", 0, if(and(UPPER($O7) = "GOL", $S7 = "SIM"), $T7+$V7, if(and(UPPER($O7) = "LATAM", $S7 = "SIM"), $T7 + $V7, "----"))) -> 0 | X7: =if($S7 = "NÃO", 0, if(and(UPPER($O7) = "GOL", $S7 = "SIM"), 0.95*($U7), if(and(UPPER($O7) = "LATAM", $S7 = "SIM"), $U7, "----"))) -> 0 | Y7: =if($W7 = "----", "Valor do reembolso?", $T7-$W7+$V7) -> 1403.99 | Z7: =if($X7 = "----", "Valor do reembolso?", $U7-$X7) -> 0
A8: 4 | B8: Heraclio Felipe | C8: DIREÇÃO GERAL | D8: RELACIONAMENTO INSTITUCIONAL | E8: 46031 | F8: 46033 | G8: =if(OR(E8 = "", F8 = ""), "", datedif(E8,F8,"D")) -> 2 | H8: AÉREO | I8: João Pessoa | J8: PB | K8: JPA | L8: Belo Horizonte | M8: MG | N8: CNF | O8: AZUL | P8: 1755 | Q8: NÃO | R8: Compra de urgência | S8: NÃO | T8: 4143.97 | U8: 0 | V8: 0 | W8: =if($S8 = "NÃO", 0, if(and(UPPER($O8) = "GOL", $S8 = "SIM"), $T8+$V8, if(and(UPPER($O8) = "LATAM", $S8 = "SIM"), $T8 + $V8, "----"))) -> 0 | X8: =if($S8 = "NÃO", 0, if(and(UPPER($O8) = "GOL", $S8 = "SIM"), 0.95*($U8), if(and(UPPER($O8) = "LATAM", $S8 = "SIM"), $U8, "----"))) -> 0 | Y8: =if($W8 = "----", "Valor do reembolso?", $T8-$W8+$V8) -> 4143.97 | Z8: =if($X8 = "----", "Valor do reembolso?", $U8-$X8) -> 0
A9: 4 | B9: Diego Regal | C9: OPERAÇÕES | D9: RELACIONAMENTO INSTITUCIONAL | E9: 46032 | F9: 46033 | G9: =if(OR(E9 = "", F9 = ""), "", datedif(E9,F9,"D")) -> 1 | H9: AÉREO | I9: João Pessoa | J9: PB | K9: JPA | L9: Belo Horizonte | M9: MG | N9: CNF | O9: LATAM | P9: 1755 | Q9: NÃO | R9: Compra de urgência | S9: NÃO | T9: 3337.99 | U9: 0 | V9: 0 | W9: =if($S9 = "NÃO", 0, if(and(UPPER($O9) = "GOL", $S9 = "SIM"), $T9+$V9, if(and(UPPER($O9) = "LATAM", $S9 = "SIM"), $T9 + $V9, "----"))) -> 0 | X9: =if($S9 = "NÃO", 0, if(and(UPPER($O9) = "GOL", $S9 = "SIM"), 0.95*($U9), if(and(UPPER($O9) = "LATAM", $S9 = "SIM"), $U9, "----"))) -> 0 | Y9: =if($W9 = "----", "Valor do reembolso?", $T9-$W9+$V9) -> 3337.99 | Z9: =if($X9 = "----", "Valor do reembolso?", $U9-$X9) -> 0
A10: 4 | B10: Heraclio Felipe | C10: DIREÇÃO GERAL | D10: RELACIONAMENTO INSTITUCIONAL | E10: 46035 | F10: 46035 | G10: =if(OR(E10 = "", F10 = ""), "", datedif(E10,F10,"D")) -> 0 | H10: AÉREO | I10: Belo Horizonte | J10: MG | K10: CNF | L10: João Pessoa | M10: PB | N10: JPA | O10: LATAM | P10: 1755 | Q10: NÃO | R10: Compra de urgência | S10: NÃO | T10: 3437.43 | U10: 0 | V10: 0 | W10: =if($S10 = "NÃO", 0, if(and(UPPER($O10) = "GOL", $S10 = "SIM"), $T10+$V10, if(and(UPPER($O10) = "LATAM", $S10 = "SIM"), $T10 + $V10, "----"))) -> 0 | X10: =if($S10 = "NÃO", 0, if(and(UPPER($O10) = "GOL", $S10 = "SIM"), 0.95*($U10), if(and(UPPER($O10) = "LATAM", $S10 = "SIM"), $U10, "----"))) -> 0 | Y10: =if($W10 = "----", "Valor do reembolso?", $T10-$W10+$V10) -> 3437.43 | Z10: =if($X10 = "----", "Valor do reembolso?", $U10-$X10) -> 0
A11: 4 | B11: Diego Regal | C11: OPERAÇÕES | D11: RELACIONAMENTO INSTITUCIONAL | E11: 46035 | F11: 46035 | G11: =if(OR(E11 = "", F11 = ""), "", datedif(E11,F11,"D")) -> 0 | H11: AÉREO | I11: Belo Horizonte | J11: MG | K11: CNF | L11: João Pessoa | M11: PB | N11: JPA | O11: LATAM | P11: 1755 | Q11: NÃO | R11: Compra de urgência | S11: NÃO | T11: 3437.43 | U11: 0 | V11: 0 | W11: =if($S11 = "NÃO", 0, if(and(UPPER($O11) = "GOL", $S11 = "SIM"), $T11+$V11, if(and(UPPER($O11) = "LATAM", $S11 = "SIM"), $T11 + $V11, "----"))) -> 0 | X11: =if($S11 = "NÃO", 0, if(and(UPPER($O11) = "GOL", $S11 = "SIM"), 0.95*($U11), if(and(UPPER($O11) = "LATAM", $S11 = "SIM"), $U11, "----"))) -> 0 | Y11: =if($W11 = "----", "Valor do reembolso?", $T11-$W11+$V11) -> 3437.43 | Z11: =if($X11 = "----", "Valor do reembolso?", $U11-$X11) -> 0
A12: 5 | B12: Helber Vieira | C12: INSTITUCIONAL | D12: RELACIONAMENTO INSTITUCIONAL | E12: 46033 | F12: 46036 | G12: =if(OR(E12 = "", F12 = ""), "", datedif(E12,F12,"D")) -> 3 | H12: AÉREO | I12: Brasília | J12: DF | K12: BSB | L12: Cuiabá | M12: MT | N12: CGB | O12: LATAM | P12: 880 | Q12: NÃO | R12: Compra de urgência | S12: NÃO | T12: 2610.77 | U12: 0 | V12: 0 | W12: =if($S12 = "NÃO", 0, if(and(UPPER($O12) = "GOL", $S12 = "SIM"), $T12+$V12, if(and(UPPER($O12) = "LATAM", $S12 = "SIM"), $T12 + $V12, "----"))) -> 0 | X12: 0 | Y12: =if($W12 = "----", "Valor do reembolso?", $T12-$W12+$V12) -> 2610.77 | Z12: =if($X12 = "----", "Valor do reembolso?", $U12-$X12) -> 0
A13: 6 | B13: Helber Vieira | C13: INSTITUCIONAL | D13: RELACIONAMENTO INSTITUCIONAL | E13: 46033 | F13: 46037 | G13: =if(OR(E13 = "", F13 = ""), "", datedif(E13,F13,"D")) -> 4 | H13: AÉREO | I13: Cuiabá | J13: MT | K13: CGB | L13: Florianópolis | M13: SC | N13: FLN | O13: LATAM | P13: 1540 | Q13: NÃO | R13: Compra de urgência | S13: NÃO | T13: 1672.65 | U13: 0 | V13: 0 | W13: =if($S13 = "NÃO", 0, if(and(UPPER($O13) = "GOL", $S13 = "SIM"), $T13+$V13, if(and(UPPER($O13) = "LATAM", $S13 = "SIM"), $T13 + $V13, "----"))) -> 0 | X13: 0 | Y13: =if($W13 = "----", "Valor do reembolso?", $T13-$W13+$V13) -> 1672.65 | Z13: 0
A14: 6 | B14: Erik Anderson | C14: PEDAGÓGICO | D14: RELACIONAMENTO INSTITUCIONAL | E14: 46033 | F14: 46037 | G14: =if(OR(E14 = "", F14 = ""), "", datedif(E14,F14,"D")) -> 4 | H14: AÉREO | I14: João Pessoa | J14: PB | K14: JPA | L14: Florianópolis | M14: SC | N14: FLN | O14: LATAM | P14: 2695 | Q14: NÃO | R14: Compra de urgência | S14: NÃO | T14: 2522.92 | U14: 0 | V14: 0 | W14: =if($S14 = "NÃO", 0, if(and(UPPER($O14) = "GOL", $S14 = "SIM"), $T14+$V14, if(and(UPPER($O14) = "LATAM", $S14 = "SIM"), $T14 + $V14, "----"))) -> 0 | X14: =if($S14 = "NÃO", 0, if(and(UPPER($O14) = "GOL", $S14 = "SIM"), 0.95*($U14), if(and(UPPER($O14) = "LATAM", $S14 = "SIM"), $U14, "----"))) -> 0 | Y14: =if($W14 = "----", "Valor do reembolso?", $T14-$W14+$V14) -> 2522.92 | Z14: =if($X14 = "----", "Valor do reembolso?", $U14-$X14) -> 0
A15: 6 | B15: Erik Anderson | C15: PEDAGÓGICO | D15: RELACIONAMENTO INSTITUCIONAL | E15: 46033 | F15: 46037 | G15: =if(OR(E15 = "", F15 = ""), "", datedif(E15,F15,"D")) -> 4 | H15: AÉREO | I15: Florianópolis | J15: SC | K15: FLN | L15: João Pessoa | M15: PB | N15: JPA | O15: LATAM | P15: 2695 | Q15: NÃO | R15: Compra de urgência | S15: NÃO | T15: 2522.92 | U15: 0 | V15: 0 | W15: =if($S15 = "NÃO", 0, if(and(UPPER($O15) = "GOL", $S15 = "SIM"), $T15+$V15, if(and(UPPER($O15) = "LATAM", $S15 = "SIM"), $T15 + $V15, "----"))) -> 0 | X15: =if($S15 = "NÃO", 0, if(and(UPPER($O15) = "GOL", $S15 = "SIM"), 0.95*($U15), if(and(UPPER($O15) = "LATAM", $S15 = "SIM"), $U15, "----"))) -> 0 | Y15: =if($W15 = "----", "Valor do reembolso?", $T15-$W15+$V15) -> 2522.92 | Z15: =if($X15 = "----", "Valor do reembolso?", $U15-$X15) -> 0
A16: 6 | B16: Diego Regal | C16: OPERAÇÕES | D16: RELACIONAMENTO INSTITUCIONAL | E16: 46033 | F16: 46037 | G16: =if(OR(E16 = "", F16 = ""), "", datedif(E16,F16,"D")) -> 4 | H16: AÉREO | I16: João Pessoa | J16: PB | K16: JPA | L16: Florianópolis | M16: SC | N16: FLN | O16: LATAM | P16: 2695 | Q16: NÃO | R16: Compra de urgência | S16: NÃO | T16: 2522.92 | U16: 0 | V16: 0 | W16: =if($S16 = "NÃO", 0, if(and(UPPER($O16) = "GOL", $S16 = "SIM"), $T16+$V16, if(and(UPPER($O16) = "LATAM", $S16 = "SIM"), $T16 + $V16, "----"))) -> 0 | X16: =if($S16 = "NÃO", 0, if(and(UPPER($O16) = "GOL", $S16 = "SIM"), 0.95*($U16), if(and(UPPER($O16) = "LATAM", $S16 = "SIM"), $U16, "----"))) -> 0 | Y16: =if($W16 = "----", "Valor do reembolso?", $T16-$W16+$V16) -> 2522.92 | Z16: =if($X16 = "----", "Valor do reembolso?", $U16-$X16) -> 0
A17: 6 | B17: Diego Regal | C17: OPERAÇÕES | D17: RELACIONAMENTO INSTITUCIONAL | E17: 46033 | F17: 46037 | G17: =if(OR(E17 = "", F17 = ""), "", datedif(E17,F17,"D")) -> 4 | H17: AÉREO | I17: Florianópolis | J17: SC | K17: FLN | L17: João Pessoa | M17: PB | N17: JPA | O17: LATAM | P17: 2695 | Q17: NÃO | R17: Compra de urgência | S17: NÃO | T17: 2522.92 | U17: 0 | V17: 0 | W17: =if($S17 = "NÃO", 0, if(and(UPPER($O17) = "GOL", $S17 = "SIM"), $T17+$V17, if(and(UPPER($O17) = "LATAM", $S17 = "SIM"), $T17 + $V17, "----"))) -> 0 | X17: =if($S17 = "NÃO", 0, if(and(UPPER($O17) = "GOL", $S17 = "SIM"), 0.95*($U17), if(and(UPPER($O17) = "LATAM", $S17 = "SIM"), $U17, "----"))) -> 0 | Y17: =if($W17 = "----", "Valor do reembolso?", $T17-$W17+$V17) -> 2522.92 | Z17: =if($X17 = "----", "Valor do reembolso?", $U17-$X17) -> 0
A18: 6 | B18: Helber Vieira | C18: INSTITUCIONAL | D18: RELACIONAMENTO INSTITUCIONAL | E18: 46033 | F18: 46038 | G18: =if(OR(E18 = "", F18 = ""), "", datedif(E18,F18,"D")) -> 5 | H18: AÉREO | I18: Florianópolis | J18: SC | K18: FLN | L18: Brasília | M18: DF | N18: BSB | O18: GOL | P18: 1320 | Q18: NÃO | R18: Compra de urgência | S18: NÃO | T18: 1043.46 | U18: 0 | V18: 0 | W18: =if($S18 = "NÃO", 0, if(and(UPPER($O18) = "GOL", $S18 = "SIM"), $T18+$V18, if(and(UPPER($O18) = "LATAM", $S18 = "SIM"), $T18 + $V18, "----"))) -> 0 | X18: =if($S18 = "NÃO", 0, if(and(UPPER($O18) = "GOL", $S18 = "SIM"), 0.95*($U18), if(and(UPPER($O18) = "LATAM", $S18 = "SIM"), $U18, "----"))) -> 0 | Y18: =if($W18 = "----", "Valor do reembolso?", $T18-$W18+$V18) -> 1043.46 | Z18: =if($X18 = "----", "Valor do reembolso?", $U18-$X18) -> 0
A19: 7 | B19: Heraclio Felipe | C19: DIREÇÃO GERAL | D19: RELACIONAMENTO INSTITUCIONAL | E19: 46041 | F19: 46041 | G19: =if(OR(E19 = "", F19 = ""), "", datedif(E19,F19,"D")) -> 0 | H19: AÉREO | I19: João Pessoa | J19: PB | K19: JPA | L19: Belo Horizonte | M19: MG | N19: CNF | O19: AZUL | P19: 1620 | Q19: NÃO | R19: Compra de urgência | S19: NÃO | T19: 3165.68 | U19: 0 | V19: 0 | W19: =if($S19 = "NÃO", 0, if(and(UPPER($O19) = "GOL", $S19 = "SIM"), $T19+$V19, if(and(UPPER($O19) = "LATAM", $S19 = "SIM"), $T19 + $V19, "----"))) -> 0 | X19: =if($S19 = "NÃO", 0, if(and(UPPER($O19) = "GOL", $S19 = "SIM"), 0.95*($U19), if(and(UPPER($O19) = "LATAM", $S19 = "SIM"), $U19, "----"))) -> 0 | Y19: =if($W19 = "----", "Valor do reembolso?", $T19-$W19+$V19) -> 3165.68 | Z19: =if($X19 = "----", "Valor do reembolso?", $U19-$X19) -> 0
A20: 7 | B20: Heraclio Felipe | C20: DIREÇÃO GERAL | D20: RELACIONAMENTO INSTITUCIONAL | E20: 46041 | F20: 46041 | G20: =if(OR(E20 = "", F20 = ""), "", datedif(E20,F20,"D")) -> 0 | H20: AÉREO | I20: Belo Horizonte | J20: MG | K20: CNF | L20: João Pessoa | M20: PB | N20: JPA | O20: AZUL | P20: 1620 | Q20: NÃO | R20: Compra de urgência | S20: NÃO | T20: 3111.68 | U20: 0 | V20: 0 | W20: =if($S20 = "NÃO", 0, if(and(UPPER($O20) = "GOL", $S20 = "SIM"), $T20+$V20, if(and(UPPER($O20) = "LATAM", $S20 = "SIM"), $T20 + $V20, "----"))) -> 0 | X20: =if($S20 = "NÃO", 0, if(and(UPPER($O20) = "GOL", $S20 = "SIM"), 0.95*($U20), if(and(UPPER($O20) = "LATAM", $S20 = "SIM"), $U20, "----"))) -> 0 | Y20: =if($W20 = "----", "Valor do reembolso?", $T20-$W20+$V20) -> 3111.68 | Z20: =if($X20 = "----", "Valor do reembolso?", $U20-$X20) -> 0
A21: 8 | B21: Helber Vieira | C21: INSTITUCIONAL | D21: RELACIONAMENTO INSTITUCIONAL | E21: 46041 | F21: 46046 | G21: =if(OR(E21 = "", F21 = ""), "", datedif(E21,F21,"D")) -> 5 | H21: AÉREO | I21: João Pessoa | J21: DF | K21: BSB | L21: João Pessoa | M21: PB | N21: JPA | O21: GOL | P21: 1720 | Q21: NÃO | R21: Compra de urgência | S21: NÃO | T21: 1467.99 | U21: 0 | V21: 0 | W21: =if($S21 = "NÃO", 0, if(and(UPPER($O21) = "GOL", $S21 = "SIM"), $T21+$V21, if(and(UPPER($O21) = "LATAM", $S21 = "SIM"), $T21 + $V21, "----"))) -> 0 | X21: 0 | Y21: =if($W21 = "----", "Valor do reembolso?", $T21-$W21+$V21) -> 1467.99 | Z21: =if($X21 = "----", "Valor do reembolso?", $U21-$X21) -> 0
A22: 9 | B22: Heraclio Felipe | C22: DIREÇÃO GERAL | D22: PROSPECÇÃO | E22: 46050 | F22: 46051 | G22: =if(OR(E22 = "", F22 = ""), "", datedif(E22,F22,"D")) -> 1 | H22: AÉREO | I22: Recife | J22: PE | K22: REC | L22: São Paulo | M22: SP | N22: CGN | O22: LATAM | P22: 2120 | Q22: NÃO | R22: Compra de urgência | S22: NÃO | T22: 3659.64 | U22: 0 | V22: 0 | W22: =if($S22 = "NÃO", 0, if(and(UPPER($O22) = "GOL", $S22 = "SIM"), $T22+$V22, if(and(UPPER($O22) = "LATAM", $S22 = "SIM"), $T22 + $V22, "----"))) -> 0 | X22: =if($S22 = "NÃO", 0, if(and(UPPER($O22) = "GOL", $S22 = "SIM"), 0.95*($U22), if(and(UPPER($O22) = "LATAM", $S22 = "SIM"), $U22, "----"))) -> 0 | Y22: =if($W22 = "----", "Valor do reembolso?", $T22-$W22+$V22) -> 3659.64 | Z22: =if($X22 = "----", "Valor do reembolso?", $U22-$X22) -> 0
A23: 9 | B23: Diego Regal | C23: OPERAÇÕES | D23: PROSPECÇÃO | E23: 46050 | F23: 46051 | G23: =if(OR(E23 = "", F23 = ""), "", datedif(E23,F23,"D")) -> 1 | H23: AÉREO | I23: Recife | J23: PE | K23: REC | L23: São Paulo | M23: SP | N23: CGN | O23: LATAM | P23: 2120 | Q23: NÃO | R23: Compra de urgência | S23: NÃO | T23: 3659.64 | U23: 0 | V23: 0 | W23: =if($S23 = "NÃO", 0, if(and(UPPER($O23) = "GOL", $S23 = "SIM"), $T23+$V23, if(and(UPPER($O23) = "LATAM", $S23 = "SIM"), $T23 + $V23, "----"))) -> 0 | X23: =if($S23 = "NÃO", 0, if(and(UPPER($O23) = "GOL", $S23 = "SIM"), 0.95*($U23), if(and(UPPER($O23) = "LATAM", $S23 = "SIM"), $U23, "----"))) -> 0 | Y23: =if($W23 = "----", "Valor do reembolso?", $T23-$W23+$V23) -> 3659.64 | Z23: =if($X23 = "----", "Valor do reembolso?", $U23-$X23) -> 0
A24: 10 | B24: Helber Vieira | C24: INSTITUCIONAL | D24: RELACIONAMENTO INSTITUCIONAL | E24: 46071 | F24: 46072 | G24: =if(OR(E24 = "", F24 = ""), "", datedif(E24,F24,"D")) -> 1 | H24: AÉREO | I24: Brasília | J24: DF | K24: BSB | L24: Florianópolis | M24: SC | N24: FLN | O24: GOL | P24: 1320 | Q24: NÃO | R24: Compra de urgência | S24: NÃO | T24: 2569.14 | U24: 0 | V24: 0 | W24: =if($S24 = "NÃO", 0, if(and(UPPER($O24) = "GOL", $S24 = "SIM"), $T24+$V24, if(and(UPPER($O24) = "LATAM", $S24 = "SIM"), $T24 + $V24, "----"))) -> 0 | X24: =if($S24 = "NÃO", 0, if(and(UPPER($O24) = "GOL", $S24 = "SIM"), 0.95*($U24), if(and(UPPER($O24) = "LATAM", $S24 = "SIM"), $U24, "----"))) -> 0 | Y24: =if($W24 = "----", "Valor do reembolso?", $T24-$W24+$V24) -> 2569.14 | Z24: =if($X24 = "----", "Valor do reembolso?", $U24-$X24) -> 0
A25: 10 | B25: Helber Vieira | C25: INSTITUCIONAL | D25: RELACIONAMENTO INSTITUCIONAL | E25: 46071 | F25: 46073 | G25: =if(OR(E25 = "", F25 = ""), "", datedif(E25,F25,"D")) -> 2 | H25: AÉREO | I25: Florianópolis | J25: SC | K25: FLN | L25: Brasília | M25: DF | N25: BSB | O25: LATAM | P25: 1320 | Q25: NÃO | R25: Compra de urgência | S25: NÃO | T25: 1765.86 | U25: 0 | V25: 0 | W25: =if($S25 = "NÃO", 0, if(and(UPPER($O25) = "GOL", $S25 = "SIM"), $T25+$V25, if(and(UPPER($O25) = "LATAM", $S25 = "SIM"), $T25 + $V25, "----"))) -> 0 | X25: =if($S25 = "NÃO", 0, if(and(UPPER($O25) = "GOL", $S25 = "SIM"), 0.95*($U25), if(and(UPPER($O25) = "LATAM", $S25 = "SIM"), $U25, "----"))) -> 0 | Y25: =if($W25 = "----", "Valor do reembolso?", $T25-$W25+$V25) -> 1765.86 | Z25: =if($X25 = "----", "Valor do reembolso?", $U25-$X25) -> 0
A26: 10 | B26: Heraclio Felipe | C26: DIREÇÃO GERAL | D26: RELACIONAMENTO INSTITUCIONAL | E26: 46072 | F26: 46072 | G26: =if(OR(E26 = "", F26 = ""), "", datedif(E26,F26,"D")) -> 0 | H26: AÉREO | I26: João Pessoa | J26: PB | K26: JPA | L26: Florianópolis | M26: SC | N26: FLN | O26: LATAM | P26: 2695 | Q26: NÃO | R26: Compra de urgência | S26: NÃO | T26: 3653.09 | U26: 0 | V26: 0 | W26: =if($S26 = "NÃO", 0, if(and(UPPER($O26) = "GOL", $S26 = "SIM"), $T26+$V26, if(and(UPPER($O26) = "LATAM", $S26 = "SIM"), $T26 + $V26, "----"))) -> 0 | X26: =if($S26 = "NÃO", 0, if(and(UPPER($O26) = "GOL", $S26 = "SIM"), 0.95*($U26), if(and(UPPER($O26) = "LATAM", $S26 = "SIM"), $U26, "----"))) -> 0 | Y26: =if($W26 = "----", "Valor do reembolso?", $T26-$W26+$V26) -> 3653.09 | Z26: =if($X26 = "----", "Valor do reembolso?", $U26-$X26) -> 0
A27: 10 | B27: Heraclio Felipe | C27: DIREÇÃO GERAL | D27: RELACIONAMENTO INSTITUCIONAL | E27: 46072 | F27: 46073 | G27: =if(OR(E27 = "", F27 = ""), "", datedif(E27,F27,"D")) -> 1 | H27: AÉREO | I27: Florianópolis | J27: SC | K27: FLN | L27: João Pessoa | M27: PB | N27: JPA | O27: LATAM | P27: 2695 | Q27: NÃO | R27: Compra de urgência | S27: NÃO | T27: 2000.86 | U27: 0 | V27: 0 | W27: =if($S27 = "NÃO", 0, if(and(UPPER($O27) = "GOL", $S27 = "SIM"), $T27+$V27, if(and(UPPER($O27) = "LATAM", $S27 = "SIM"), $T27 + $V27, "----"))) -> 0 | X27: =if($S27 = "NÃO", 0, if(and(UPPER($O27) = "GOL", $S27 = "SIM"), 0.95*($U27), if(and(UPPER($O27) = "LATAM", $S27 = "SIM"), $U27, "----"))) -> 0 | Y27: =if($W27 = "----", "Valor do reembolso?", $T27-$W27+$V27) -> 2000.86 | Z27: =if($X27 = "----", "Valor do reembolso?", $U27-$X27) -> 0
A28: 11 | B28: Heraclio Felipe | C28: DIREÇÃO GERAL | D28: RELACIONAMENTO INSTITUCIONAL | E28: 46072 | F28: 46076 | G28: =if(OR(E28 = "", F28 = ""), "", datedif(E28,F28,"D")) -> 4 | H28: AÉREO | I28: João Pessoa | J28: PB | K28: JPA | L28: Rio de Janeiro | M28: RJ | N28: GIG | O28: LATAM | P28: 1970 | Q28: NÃO | R28: Compra de urgência | S28: NÃO | T28: 3187.99 | U28: 0 | V28: 0 | W28: =if($S28 = "NÃO", 0, if(and(UPPER($O28) = "GOL", $S28 = "SIM"), $T28+$V28, if(and(UPPER($O28) = "LATAM", $S28 = "SIM"), $T28 + $V28, "----"))) -> 0 | X28: =if($S28 = "NÃO", 0, if(and(UPPER($O28) = "GOL", $S28 = "SIM"), 0.95*($U28), if(and(UPPER($O28) = "LATAM", $S28 = "SIM"), $U28, "----"))) -> 0 | Y28: =if($W28 = "----", "Valor do reembolso?", $T28-$W28+$V28) -> 3187.99 | Z28: =if($X28 = "----", "Valor do reembolso?", $U28-$X28) -> 0
A29: 11 | B29: Helber Vieira | C29: INSTITUCIONAL | D29: RELACIONAMENTO INSTITUCIONAL | E29: 46074 | F29: 46076 | G29: =if(OR(E29 = "", F29 = ""), "", datedif(E29,F29,"D")) -> 2 | H29: AÉREO | I29: Brasília | J29: DF | K29: BSB | L29: Rio de Janeiro | M29: RJ | N29: GIG | O29: LATAM | P29: 930 | Q29: NÃO | R29: Compra de urgência | S29: NÃO | T29: 1916.77 | U29: 0 | V29: 0 | W29: =if($S29 = "NÃO", 0, if(and(UPPER($O29) = "GOL", $S29 = "SIM"), $T29+$V29, if(and(UPPER($O29) = "LATAM", $S29 = "SIM"), $T29 + $V29, "----"))) -> 0 | X29: =if($S29 = "NÃO", 0, if(and(UPPER($O29) = "GOL", $S29 = "SIM"), 0.95*($U29), if(and(UPPER($O29) = "LATAM", $S29 = "SIM"), $U29, "----"))) -> 0 | Y29: =if($W29 = "----", "Valor do reembolso?", $T29-$W29+$V29) -> 1916.77 | Z29: =if($X29 = "----", "Valor do reembolso?", $U29-$X29) -> 0
A30: 11 | B30: Heraclio Felipe | C30: DIREÇÃO GERAL | D30: RELACIONAMENTO INSTITUCIONAL | E30: 46076 | F30: 46076 | G30: =if(OR(E30 = "", F30 = ""), "", datedif(E30,F30,"D")) -> 0 | H30: AÉREO | I30: Rio de Janeiro | J30: RJ | K30: GIG | L30: Brasília | M30: DF | N30: BSB | O30: LATAM | P30: 930 | Q30: NÃO | R30: Compra de urgência | S30: NÃO | T30: 1607.01 | U30: 0 | V30: 0 | W30: =if($S30 = "NÃO", 0, if(and(UPPER($O30) = "GOL", $S30 = "SIM"), $T30+$V30, if(and(UPPER($O30) = "LATAM", $S30 = "SIM"), $T30 + $V30, "----"))) -> 0 | X30: =if($S30 = "NÃO", 0, if(and(UPPER($O30) = "GOL", $S30 = "SIM"), 0.95*($U30), if(and(UPPER($O30) = "LATAM", $S30 = "SIM"), $U30, "----"))) -> 0 | Y30: =if($W30 = "----", "Valor do reembolso?", $T30-$W30+$V30) -> 1607.01 | Z30: =if($X30 = "----", "Valor do reembolso?", $U30-$X30) -> 0
A31: 11 | B31: Helber Vieira | C31: INSTITUCIONAL | D31: RELACIONAMENTO INSTITUCIONAL | E31: 46076 | F31: 46076 | G31: =if(OR(E31 = "", F31 = ""), "", datedif(E31,F31,"D")) -> 0 | H31: AÉREO | I31: Rio de Janeiro | J31: RJ | K31: GIG | L31: Brasília | M31: DF | N31: BSB | O31: LATAM | P31: 930 | Q31: NÃO | R31: Compra de urgência | S31: NÃO | T31: 1607.01 | U31: 0 | V31: 0 | W31: =if($S31 = "NÃO", 0, if(and(UPPER($O31) = "GOL", $S31 = "SIM"), $T31+$V31, if(and(UPPER($O31) = "LATAM", $S31 = "SIM"), $T31 + $V31, "----"))) -> 0 | X31: =if($S31 = "NÃO", 0, if(and(UPPER($O31) = "GOL", $S31 = "SIM"), 0.95*($U31), if(and(UPPER($O31) = "LATAM", $S31 = "SIM"), $U31, "----"))) -> 0 | Y31: =if($W31 = "----", "Valor do reembolso?", $T31-$W31+$V31) -> 1607.01 | Z31: =if($X31 = "----", "Valor do reembolso?", $U31-$X31) -> 0
A32: 11 | B32: Heraclio Felipe | C32: DIREÇÃO GERAL | D32: RELACIONAMENTO INSTITUCIONAL | E32: 46076 | F32: 46078 | G32: =if(OR(E32 = "", F32 = ""), "", datedif(E32,F32,"D")) -> 2 | H32: AÉREO | I32: Brasília | J32: DF | K32: BSB | L32: João Pessoa | M32: PB | N32: JPA | O32: LATAM | P32: 1700 | Q32: NÃO | R32: Compra de urgência | S32: NÃO | U32: 0 | V32: 0 | W32: =if($S32 = "NÃO", 0, if(and(UPPER($O32) = "GOL", $S32 = "SIM"), $T32+$V32, if(and(UPPER($O32) = "LATAM", $S32 = "SIM"), $T32 + $V32, "----"))) -> 0 | X32: =if($S32 = "NÃO", 0, if(and(UPPER($O32) = "GOL", $S32 = "SIM"), 0.95*($U32), if(and(UPPER($O32) = "LATAM", $S32 = "SIM"), $U32, "----"))) -> 0 | Y32: =if($W32 = "----", "Valor do reembolso?", $T32-$W32+$V32) -> 0 | Z32: =if($X32 = "----", "Valor do reembolso?", $U32-$X32) -> 0
A33: 11 | B33: Diego Regal | C33: OPERAÇÕES | D33: RELACIONAMENTO INSTITUCIONAL | E33: 46070 | F33: 46076 | G33: =if(OR(E33 = "", F33 = ""), "", datedif(E33,F33,"D")) -> 6 | H33: AÉREO | I33: João Pessoa | J33: PB | K33: JPA | L33: Brasília | M33: DF | N33: BSB | O33: LATAM | P33: 1700 | Q33: NÃO | R33: Tempo moderado | S33: NÃO | T33: 2105.99 | U33: 0 | V33: 0 | W33: =if($S33 = "NÃO", 0, if(and(UPPER($O33) = "GOL", $S33 = "SIM"), $T33+$V33, if(and(UPPER($O33) = "LATAM", $S33 = "SIM"), $T33 + $V33, "----"))) -> 0 | X33: =if($S33 = "NÃO", 0, if(and(UPPER($O33) = "GOL", $S33 = "SIM"), 0.95*($U33), if(and(UPPER($O33) = "LATAM", $S33 = "SIM"), $U33, "----"))) -> 0 | Y33: =if($W33 = "----", "Valor do reembolso?", $T33-$W33+$V33) -> 2105.99 | Z33: =if($X33 = "----", "Valor do reembolso?", $U33-$X33) -> 0
A34: 11 | B34: Erik Anderson | C34: PEDAGÓGICO | D34: RELACIONAMENTO INSTITUCIONAL | E34: 46070 | F34: 46076 | G34: =if(OR(E34 = "", F34 = ""), "", datedif(E34,F34,"D")) -> 6 | H34: AÉREO | I34: João Pessoa | J34: PB | K34: JPA | L34: Brasília | M34: DF | N34: BSB | O34: LATAM | P34: 1700 | Q34: NÃO | R34: Tempo moderado | S34: NÃO | T34: 2105.99 | U34: 0 | V34: 0 | W34: =if($S34 = "NÃO", 0, if(and(UPPER($O34) = "GOL", $S34 = "SIM"), $T34+$V34, if(and(UPPER($O34) = "LATAM", $S34 = "SIM"), $T34 + $V34, "----"))) -> 0 | X34: =if($S34 = "NÃO", 0, if(and(UPPER($O34) = "GOL", $S34 = "SIM"), 0.95*($U34), if(and(UPPER($O34) = "LATAM", $S34 = "SIM"), $U34, "----"))) -> 0 | Y34: =if($W34 = "----", "Valor do reembolso?", $T34-$W34+$V34) -> 2105.99 | Z34: =if($X34 = "----", "Valor do reembolso?", $U34-$X34) -> 0
A35: 11 | B35: Diego Regal | C35: OPERAÇÕES | D35: RELACIONAMENTO INSTITUCIONAL | E35: 46070 | F35: 46078 | G35: =if(OR(E35 = "", F35 = ""), "", datedif(E35,F35,"D")) -> 8 | H35: AÉREO | I35: Brasília | J35: DF | K35: BSB | L35: João Pessoa | M35: PB | N35: JPA | O35: LATAM | P35: 1700 | Q35: NÃO | R35: Tempo moderado | S35: NÃO | T35: 1067.77 | U35: 0 | V35: 0 | W35: =if($S35 = "NÃO", 0, if(and(UPPER($O35) = "GOL", $S35 = "SIM"), $T35+$V35, if(and(UPPER($O35) = "LATAM", $S35 = "SIM"), $T35 + $V35, "----"))) -> 0 | X35: =if($S35 = "NÃO", 0, if(and(UPPER($O35) = "GOL", $S35 = "SIM"), 0.95*($U35), if(and(UPPER($O35) = "LATAM", $S35 = "SIM"), $U35, "----"))) -> 0 | Y35: =if($W35 = "----", "Valor do reembolso?", $T35-$W35+$V35) -> 1067.77 | Z35: =if($X35 = "----", "Valor do reembolso?", $U35-$X35) -> 0
A36: 11 | B36: Erik Anderson | C36: PEDAGÓGICO | D36: RELACIONAMENTO INSTITUCIONAL | E36: 46070 | F36: 46078 | G36: =if(OR(E36 = "", F36 = ""), "", datedif(E36,F36,"D")) -> 8 | H36: AÉREO | I36: Brasília | J36: DF | K36: BSB | L36: João Pessoa | M36: PB | N36: JPA | O36: LATAM | P36: 1700 | Q36: NÃO | R36: Tempo moderado | S36: NÃO | T36: 1067.77 | U36: 0 | V36: 0 | W36: =if($S36 = "NÃO", 0, if(and(UPPER($O36) = "GOL", $S36 = "SIM"), $T36+$V36, if(and(UPPER($O36) = "LATAM", $S36 = "SIM"), $T36 + $V36, "----"))) -> 0 | X36: =if($S36 = "NÃO", 0, if(and(UPPER($O36) = "GOL", $S36 = "SIM"), 0.95*($U36), if(and(UPPER($O36) = "LATAM", $S36 = "SIM"), $U36, "----"))) -> 0 | Y36: =if($W36 = "----", "Valor do reembolso?", $T36-$W36+$V36) -> 1067.77 | Z36: =if($X36 = "----", "Valor do reembolso?", $U36-$X36) -> 0
A37: 12 | B37: Vania Beneveli | C37: PEDAGÓGICO | D37: FORMAÇÃO | E37: 46076 | F37: 46082 | G37: =if(OR(E37 = "", F37 = ""), "", datedif(E37,F37,"D")) -> 6 | H37: AÉREO | I37: Brasília | J37: DF | K37: BSB | L37: João Pessoa | M37: PB | N37: JPA | O37: GOL | P37: 1700 | Q37: NÃO | R37: Tempo moderado | S37: NÃO | T37: 2241.38 | U37: 0 | W37: =if($S37 = "NÃO", 0, if(and(UPPER($O37) = "GOL", $S37 = "SIM"), $T37+$V37, if(and(UPPER($O37) = "LATAM", $S37 = "SIM"), $T37 + $V37, "----"))) -> 0 | X37: =if($S37 = "NÃO", 0, if(and(UPPER($O37) = "GOL", $S37 = "SIM"), 0.95*($U37), if(and(UPPER($O37) = "LATAM", $S37 = "SIM"), $U37, "----"))) -> 0 | Y37: =if($W37 = "----", "Valor do reembolso?", $T37-$W37+$V37) -> 2241.38 | Z37: =if($X37 = "----", "Valor do reembolso?", $U37-$X37) -> 0
A38: 12 | B38: Vania Beneveli | C38: PEDAGÓGICO | D38: FORMAÇÃO | E38: 46076 | F38: 46085 | G38: =if(OR(E38 = "", F38 = ""), "", datedif(E38,F38,"D")) -> 9 | H38: AÉREO | I38: João Pessoa | J38: PB | K38: JPA | L38: Brasília | M38: DF | N38: BSB | O38: GOL | P38: 1700 | Q38: NÃO | R38: Tempo moderado | S38: NÃO | T38: 2241.38 | U38: 0 | V38: 0 | W38: =if($S38 = "NÃO", 0, if(and(UPPER($O38) = "GOL", $S38 = "SIM"), $T38+$V38, if(and(UPPER($O38) = "LATAM", $S38 = "SIM"), $T38 + $V38, "----"))) -> 0 | X38: =if($S38 = "NÃO", 0, if(and(UPPER($O38) = "GOL", $S38 = "SIM"), 0.95*($U38), if(and(UPPER($O38) = "LATAM", $S38 = "SIM"), $U38, "----"))) -> 0 | Y38: =if($W38 = "----", "Valor do reembolso?", $T38-$W38+$V38) -> 2241.38 | Z38: =if($X38 = "----", "Valor do reembolso?", $U38-$X38) -> 0
A39: 13 | B39: Heraclio Felipe | C39: DIREÇÃO GERAL | D39: RELACIONAMENTO INSTITUCIONAL | E39: 46082 | F39: 46083 | G39: =if(OR(E39 = "", F39 = ""), "", datedif(E39,F39,"D")) -> 1 | H39: AÉREO | I39: João Pessoa | J39: PB | K39: JPA | L39: Brasília | M39: DF | N39: BSB | O39: GOL | P39: 1700 | Q39: NÃO | R39: Compra de urgência | S39: NÃO | T39: 3643.09 | U39: 0 | V39: 0 | W39: =if($S39 = "NÃO", 0, if(and(UPPER($O39) = "GOL", $S39 = "SIM"), $T39+$V39, if(and(UPPER($O39) = "LATAM", $S39 = "SIM"), $T39 + $V39, "----"))) -> 0 | X39: =if($S39 = "NÃO", 0, if(and(UPPER($O39) = "GOL", $S39 = "SIM"), 0.95*($U39), if(and(UPPER($O39) = "LATAM", $S39 = "SIM"), $U39, "----"))) -> 0 | Y39: =if($W39 = "----", "Valor do reembolso?", $T39-$W39+$V39) -> 3643.09 | Z39: =if($X39 = "----", "Valor do reembolso?", $U39-$X39) -> 0
A40: 13 | B40: Heraclio Felipe | C40: DIREÇÃO GERAL | D40: RELACIONAMENTO INSTITUCIONAL | E40: 46084 | F40: 46084 | G40: =if(OR(E40 = "", F40 = ""), "", datedif(E40,F40,"D")) -> 0 | H40: AÉREO | I40: Brasília | J40: DF | K40: BSB | L40: João Pessoa | M40: PB | N40: JPA | O40: LATAM | P40: 0 | Q40: NÃO | R40: Compra de urgência | S40: SIM | T40: 3083.77 | U40: 0 | V40: 0 | W40: 0 | X40: =if($S40 = "NÃO", 0, if(and(UPPER($O40) = "GOL", $S40 = "SIM"), 0.95*($U40), if(and(UPPER($O40) = "LATAM", $S40 = "SIM"), $U40, "----"))) -> 0 | Y40: =if($W40 = "----", "Valor do reembolso?", $T40-$W40+$V40) -> 3083.77 | Z40: =if($X40 = "----", "Valor do reembolso?", $U40-$X40) -> 0
...

Sheet VIAGENS_PROXIMAS
A1: ID da viagem (interno) | B1: Nome do viajante | C1: Data da viagem | D1: Quantos dias faltam?
A2: =IFERROR(__xludf.DUMMYFUNCTION("if( isna(filter(TRECHOS_LONGOS!A:A, DATEDIF(TODAY(), TRECHOS_LONGOS!$F:$F, ""D"") <= 1)), """", filter(TRECHOS_LONGOS!A:A, DATEDIF(TODAY(), TRECHOS_LONGOS!$F:$F, ""D"") <= 1))"),"") | B2: =IFERROR(__xludf.DUMMYFUNCTION("if( isna(filter(TRECHOS_LONGOS!B:B, DATEDIF(TODAY(), TRECHOS_LONGOS!$F:$F, ""D"") <= 1)), """", filter(TRECHOS_LONGOS!B:B, DATEDIF(TODAY(), TRECHOS_LONGOS!$F:$F, ""D"") <= 1))"),"") | C2: =IFERROR(__xludf.DUMMYFUNCTION("if( isna(filter(TRECHOS_LONGOS!F:F, DATEDIF(TODAY(), TRECHOS_LONGOS!$F:$F, ""D"") <= 1)), """", filter(TRECHOS_LONGOS!F:F, DATEDIF(TODAY(), TRECHOS_LONGOS!$F:$F, ""D"") <= 1))"),"") | D2: =IFERROR(__xludf.DUMMYFUNCTION("if( isna(filter(DATEDIF(TODAY(), TRECHOS_LONGOS!$F:$F, ""D""), DATEDIF(TODAY(), TRECHOS_LONGOS!$F:$F, ""D"") <= 1)), """", filter(DATEDIF(TODAY(), TRECHOS_LONGOS!$F:$F, ""D""), DATEDIF(TODAY(), TRECHOS_LONGOS!$F:$F, ""D"") <= 1))"),"")

Sheet HOSPEDAGEM
A1: ID da viagem (Interno) | B1: Nome do viajante | C1: Hotel | D1: Data da compra | E1: Data do Check-In | F1: Data do Check-Out | G1: Duração da Estadia (Dias) | H1: Valores das Diárias (R$) | I1: Valor Médio da Diária (R$) | J1: Valor Total da Estadia (R$)
A2: 1 | B2: Vania Beneveli | C2: Rede Andrade Solmar | D2: 46014 | E2: 46026 | F2: 46029 | G2: =if(OR(E2 = "", F2 = ""), "", IF(datedif(E2,F2,"D") = 0, 1, datedif(E2,F2,"D"))) -> 3 | H2: 440,01; 504,77; 459,44 | I2: =IFERROR(__xludf.DUMMYFUNCTION("if($H2="""", """", AVERAGE(split($H2, "";"")))"),468.0733333333333) -> 468.07333 | J2: =IFERROR(__xludf.DUMMYFUNCTION("if($H2="""", """", SUM(split($H2, "";"")))"),1404.22) -> 1404.22
A3: 2 | B3: Simone Cortes | C3: Hotel Annamar Premium | D3: 46014 | E3: 46029 | F3: 46031 | G3: =if(OR(E3 = "", F3 = ""), "", IF(datedif(E3,F3,"D") = 0, 1, datedif(E3,F3,"D"))) -> 2 | H3: 565,88; 565,88 | I3: =IFERROR(__xludf.DUMMYFUNCTION("if($H3="""", """", AVERAGE(split($H3, "";"")))"),565.88) -> 565.88 | J3: =IFERROR(__xludf.DUMMYFUNCTION("if(H3="""", """", SUM(split(H3, "";"")))"),1131.76) -> 1131.76
A4: 3 | B4: Alexandre Carvalho | C4: Rede Andrade Solmar | D4: 46014 | E4: 46033 | F4: 46036 | G4: =if(OR(E4 = "", F4 = ""), "", IF(datedif(E4,F4,"D") = 0, 1, datedif(E4,F4,"D"))) -> 3 | H4: 551,5; 551,5; 565,98 | I4: =IFERROR(__xludf.DUMMYFUNCTION("if($H4="""", """", AVERAGE(split($H4, "";"")))"),556.3266666666667) -> 556.32667 | J4: =IFERROR(__xludf.DUMMYFUNCTION("if(H4="""", """", SUM(split(H4, "";"")))"),1668.98) -> 1668.98
A5: 4 | B5: Heraclio Pianco | C5: Hilton Garden Inn | D5: 46031 | E5: 46033 | F5: 46035 | G5: =if(OR(E5 = "", F5 = ""), "", IF(datedif(E5,F5,"D") = 0, 1, datedif(E5,F5,"D"))) -> 2 | H5: 445,79; 445,79 | I5: =IFERROR(__xludf.DUMMYFUNCTION("if($H5="""", """", AVERAGE(split($H5, "";"")))"),445.79) -> 445.79 | J5: =IFERROR(__xludf.DUMMYFUNCTION("if(H5="""", """", SUM(split(H5, "";"")))"),891.58) -> 891.58
A6: 4 | B6: Diego Regal | C6: Hilton Garden Inn | D6: 46032 | E6: 46033 | F6: 46035 | G6: =if(OR(E6 = "", F6 = ""), "", IF(datedif(E6,F6,"D") = 0, 1, datedif(E6,F6,"D"))) -> 2 | H6: 477,00; 477,00 | I6: =IFERROR(__xludf.DUMMYFUNCTION("if($H6="""", """", AVERAGE(split($H6, "";"")))"),477.0) -> 477 | J6: =IFERROR(__xludf.DUMMYFUNCTION("if(H6="""", """", SUM(split(H6, "";"")))"),954.0) -> 954
A7: 4 | B7: Heraclio Pianco | C7: Hilton Garden Inn | D7: 46035 | E7: 46035 | F7: 46035 | G7: =if(OR(E7 = "", F7 = ""), "", IF(datedif(E7,F7,"D") = 0, 1, datedif(E7,F7,"D"))) -> 1 | H7: 385.87 | I7: =IFERROR(__xludf.DUMMYFUNCTION("if($H7="""", """", AVERAGE(split($H7, "";"")))"),385.87) -> 385.87 | J7: =IFERROR(__xludf.DUMMYFUNCTION("if(H7="""", """", SUM(split(H7, "";"")))"),385.87) -> 385.87
A8: 4 | B8: Diego Regal | C8: Hilton Garden Inn | D8: 46035 | E8: 46035 | F8: 46035 | G8: =if(OR(E8 = "", F8 = ""), "", IF(datedif(E8,F8,"D") = 0, 1, datedif(E8,F8,"D"))) -> 1 | H8: 385.87 | I8: =IFERROR(__xludf.DUMMYFUNCTION("if($H8="""", """", AVERAGE(split($H8, "";"")))"),385.87) -> 385.87 | J8: =IFERROR(__xludf.DUMMYFUNCTION("if(H8="""", """", SUM(split(H8, "";"")))"),385.87) -> 385.87
A9: 7 | B9: Erik Anderson | C9: Hotel | D9: 46037 | E9: 46037 | F9: 46037 | G9: =if(OR(E9 = "", F9 = ""), "", IF(datedif(E9,F9,"D") = 0, 1, datedif(E9,F9,"D"))) -> 1 | H9: 456 | I9: =IFERROR(__xludf.DUMMYFUNCTION("if($H9="""", """", AVERAGE(split($H9, "";"")))"),456.0) -> 456 | J9: =IFERROR(__xludf.DUMMYFUNCTION("if(H9="""", """", SUM(split(H9, "";"")))"),456.0) -> 456
A10: 11 | B10: Erik Anderson | C10: Hotel Meliá Brasil 21 | D10: 46075 | E10: 46076 | F10: 46078 | G10: =if(OR(E10 = "", F10 = ""), "", IF(datedif(E10,F10,"D") = 0, 1, datedif(E10,F10,"D"))) -> 2 | H10: 607,25; 607,25 | I10: =IFERROR(__xludf.DUMMYFUNCTION("if($H10="""", """", AVERAGE(split($H10, "";"")))"),607.25) -> 607.25 | J10: =IFERROR(__xludf.DUMMYFUNCTION("if(H10="""", """", SUM(split(H10, "";"")))"),1214.5) -> 1214.5
A11: 11 | B11: Diego Regal | C11: Hotel Meliá Brasil 21 | D11: 46075 | E11: 46076 | F11: 46078 | G11: =if(OR(E11 = "", F11 = ""), "", IF(datedif(E11,F11,"D") = 0, 1, datedif(E11,F11,"D"))) -> 2 | H11: 607,25; 607,25 | I11: =IFERROR(__xludf.DUMMYFUNCTION("if($H11="""", """", AVERAGE(split($H11, "";"")))"),607.25) -> 607.25 | J11: =IFERROR(__xludf.DUMMYFUNCTION("if(H11="""", """", SUM(split(H11, "";"")))"),1214.5) -> 1214.5
A12: 11 | B12: Heraclio Pianco | C12: Hotel Meliá Brasil 21 | D12: 46075 | E12: 46076 | F12: 46078 | G12: =if(OR(E12 = "", F12 = ""), "", IF(datedif(E12,F12,"D") = 0, 1, datedif(E12,F12,"D"))) -> 2 | H12: 607,25; 607,25 | I12: =IFERROR(__xludf.DUMMYFUNCTION("if($H12="""", """", AVERAGE(split($H12, "";"")))"),607.25) -> 607.25 | J12: =IFERROR(__xludf.DUMMYFUNCTION("if(H12="""", """", SUM(split(H12, "";"")))"),1214.5) -> 1214.5
A13: 12 | B13: Vania Beneveli | C13: Nord Class Rio 83 | D13: 46076 | E13: 46082 | F13: 46085 | G13: =if(OR(E13 = "", F13 = ""), "", IF(datedif(E13,F13,"D") = 0, 1, datedif(E13,F13,"D"))) -> 3 | H13: 337,83; 337,83; 337,83 | I13: =IFERROR(__xludf.DUMMYFUNCTION("if($H13="""", """", AVERAGE(split($H13, "";"")))"),337.83) -> 337.83 | J13: =IFERROR(__xludf.DUMMYFUNCTION("if(H13="""", """", SUM(split(H13, "";"")))"),1013.49) -> 1013.49
A14: 13 | B14: Heraclio Pianco | C14: Hotel Meliá Brasil 21 | D14: 46081 | E14: 46083 | F14: 46084 | G14: =if(OR(E14 = "", F14 = ""), "", IF(datedif(E14,F14,"D") = 0, 1, datedif(E14,F14,"D"))) -> 1 | H14: 955.5 | I14: =IFERROR(__xludf.DUMMYFUNCTION("if($H14="""", """", AVERAGE(split($H14, "";"")))"),955.5) -> 955.5 | J14: =IFERROR(__xludf.DUMMYFUNCTION("if(H14="""", """", SUM(split(H14, "";"")))"),955.5) -> 955.5
A15: 13 | B15: Heraclio Pianco | C15: Hotel Meliá Brasil 21 | D15: 46082 | E15: 46084 | F15: 46085 | G15: =if(OR(E15 = "", F15 = ""), "", IF(datedif(E15,F15,"D") = 0, 1, datedif(E15,F15,"D"))) -> 1 | H15: 1190.11 | I15: =IFERROR(__xludf.DUMMYFUNCTION("if($H15="""", """", AVERAGE(split($H15, "";"")))"),1190.11) -> 1190.11 | J15: =IFERROR(__xludf.DUMMYFUNCTION("if(H15="""", """", SUM(split(H15, "";"")))"),1190.11) -> 1190.11
A16: 14 | B16: Leandro Felix | C16: Victory Business Hotel | D16: 46108 | E16: 46084 | F16: 46086 | G16: =if(OR(E16 = "", F16 = ""), "", IF(datedif(E16,F16,"D") = 0, 1, datedif(E16,F16,"D"))) -> 2 | H16: 251,84; 251,84 | I16: =IFERROR(__xludf.DUMMYFUNCTION("if($H16="""", """", AVERAGE(split($H16, "";"")))"),251.84) -> 251.84 | J16: =IFERROR(__xludf.DUMMYFUNCTION("if(H16="""", """", SUM(split(H16, "";"")))"),503.68) -> 503.68
A17: 14 | B17: Mikaella Pedrosa | C17: Victory Business Hotel | D17: 46108 | E17: 46084 | F17: 46086 | G17: =if(OR(E17 = "", F17 = ""), "", IF(datedif(E17,F17,"D") = 0, 1, datedif(E17,F17,"D"))) -> 2 | H17: 251,84; 251,84 | I17: =IFERROR(__xludf.DUMMYFUNCTION("if($H17="""", """", AVERAGE(split($H17, "";"")))"),251.84) -> 251.84 | J17: =IFERROR(__xludf.DUMMYFUNCTION("if(H17="""", """", SUM(split(H17, "";"")))"),503.68) -> 503.68
A18: 16 | B18: Heraclio Pianco | C18: Hotel Meliá Brasil 21 | D18: 46090 | E18: 46091 | F18: 46092 | G18: =if(OR(E18 = "", F18 = ""), "", IF(datedif(E18,F18,"D") = 0, 1, datedif(E18,F18,"D"))) -> 1 | H18: 1944.27 | I18: =IFERROR(__xludf.DUMMYFUNCTION("if($H18="""", """", AVERAGE(split($H18, "";"")))"),1944.27) -> 1944.27 | J18: =IFERROR(__xludf.DUMMYFUNCTION("if(H18="""", """", SUM(split(H18, "";"")))"),1944.27) -> 1944.27
A19: 17 | B19: Alexandre Carvalho | C19: Littoral Hotel | D19: 46078 | E19: 46093 | F19: 46095 | G19: =if(OR(E19 = "", F19 = ""), "", IF(datedif(E19,F19,"D") = 0, 1, datedif(E19,F19,"D"))) -> 2 | H19: 288,01; 288,01 | I19: =IFERROR(__xludf.DUMMYFUNCTION("if($H19="""", """", AVERAGE(split($H19, "";"")))"),288.01) -> 288.01 | J19: =IFERROR(__xludf.DUMMYFUNCTION("if(H19="""", """", SUM(split(H19, "";"")))"),576.02) -> 576.02
A20: 18 | B20: Heraclio Pianco | C20: Novo Hotel RJ Santos Dumont | D20: 46096 | E20: 46097 | F20: 46098 | G20: =if(OR(E20 = "", F20 = ""), "", IF(datedif(E20,F20,"D") = 0, 1, datedif(E20,F20,"D"))) -> 1 | H20: 700.24 | I20: =IFERROR(__xludf.DUMMYFUNCTION("if($H20="""", """", AVERAGE(split($H20, "";"")))"),700.24) -> 700.24 | J20: =IFERROR(__xludf.DUMMYFUNCTION("if(H20="""", """", SUM(split(H20, "";"")))"),700.24) -> 700.24
A21: 18 | B21: Diego Regal | C21: Novo Hotel RJ Santos Dumont | D21: 46096 | E21: 46097 | F21: 46098 | G21: =if(OR(E21 = "", F21 = ""), "", IF(datedif(E21,F21,"D") = 0, 1, datedif(E21,F21,"D"))) -> 1 | H21: 700.24 | I21: =IFERROR(__xludf.DUMMYFUNCTION("if($H21="""", """", AVERAGE(split($H21, "";"")))"),700.24) -> 700.24 | J21: =IFERROR(__xludf.DUMMYFUNCTION("if(H21="""", """", SUM(split(H21, "";"")))"),700.24) -> 700.24
A22: 18 | B22: Erik Anderson | C22: Novo Hotel RJ Santos Dumont | D22: 46096 | E22: 46097 | F22: 46098 | G22: =if(OR(E22 = "", F22 = ""), "", IF(datedif(E22,F22,"D") = 0, 1, datedif(E22,F22,"D"))) -> 1 | H22: 700.24 | I22: =IFERROR(__xludf.DUMMYFUNCTION("if($H22="""", """", AVERAGE(split($H22, "";"")))"),700.24) -> 700.24 | J22: =IFERROR(__xludf.DUMMYFUNCTION("if(H22="""", """", SUM(split(H22, "";"")))"),700.24) -> 700.24
A23: 18 | B23: Helber Vieira | C23: Novo Hotel RJ Santos Dumont | D23: 46096 | E23: 46097 | F23: 46098 | G23: =if(OR(E23 = "", F23 = ""), "", IF(datedif(E23,F23,"D") = 0, 1, datedif(E23,F23,"D"))) -> 1 | H23: 700.24 | I23: =IFERROR(__xludf.DUMMYFUNCTION("if($H23="""", """", AVERAGE(split($H23, "";"")))"),700.24) -> 700.24 | J23: =IFERROR(__xludf.DUMMYFUNCTION("if(H23="""", """", SUM(split(H23, "";"")))"),700.24) -> 700.24
A24: 20 | B24: Heraclio Pianco | C24: Wydham São Paulo Ibirapuera | D24: 46096 | E24: 46098 | F24: 46099 | G24: =if(OR(E24 = "", F24 = ""), "", IF(datedif(E24,F24,"D") = 0, 1, datedif(E24,F24,"D"))) -> 1 | H24: 642.13 | I24: =IFERROR(__xludf.DUMMYFUNCTION("if($H24="""", """", AVERAGE(split($H24, "";"")))"),642.13) -> 642.13 | J24: =IFERROR(__xludf.DUMMYFUNCTION("if(H24="""", """", SUM(split(H24, "";"")))"),642.13) -> 642.13
A25: 20 | B25: Diego Regal | C25: Wydham São Paulo Ibirapuera | D25: 46096 | E25: 46098 | F25: 46099 | G25: =if(OR(E25 = "", F25 = ""), "", IF(datedif(E25,F25,"D") = 0, 1, datedif(E25,F25,"D"))) -> 1 | H25: 642.13 | I25: =IFERROR(__xludf.DUMMYFUNCTION("if($H25="""", """", AVERAGE(split($H25, "";"")))"),642.13) -> 642.13 | J25: =IFERROR(__xludf.DUMMYFUNCTION("if(H25="""", """", SUM(split(H25, "";"")))"),642.13) -> 642.13
A26: 20 | B26: Erik Anderson | C26: Wydham São Paulo Ibirapuera | D26: 46096 | E26: 46098 | F26: 46099 | G26: =if(OR(E26 = "", F26 = ""), "", IF(datedif(E26,F26,"D") = 0, 1, datedif(E26,F26,"D"))) -> 1 | H26: 642.13 | I26: =IFERROR(__xludf.DUMMYFUNCTION("if($H26="""", """", AVERAGE(split($H26, "";"")))"),642.13) -> 642.13 | J26: =IFERROR(__xludf.DUMMYFUNCTION("if(H26="""", """", SUM(split(H26, "";"")))"),642.13) -> 642.13
A27: 20 | B27: Helber Vieira | C27: Wydham São Paulo Ibirapuera | D27: 46096 | E27: 46098 | F27: 46099 | G27: =if(OR(E27 = "", F27 = ""), "", IF(datedif(E27,F27,"D") = 0, 1, datedif(E27,F27,"D"))) -> 1 | H27: 642.13 | I27: =IFERROR(__xludf.DUMMYFUNCTION("if($H27="""", """", AVERAGE(split($H27, "";"")))"),642.13) -> 642.13 | J27: =IFERROR(__xludf.DUMMYFUNCTION("if(H27="""", """", SUM(split(H27, "";"")))"),642.13) -> 642.13
A28: 21 | B28: Francisco Wericson | C28: Victory Business Hotel | D28: 46098 | E28: 46099 | F28: 46101 | G28: =if(OR(E28 = "", F28 = ""), "", IF(datedif(E28,F28,"D") = 0, 1, datedif(E28,F28,"D"))) -> 2 | H28: 288,1; 288,1 | I28: =IFERROR(__xludf.DUMMYFUNCTION("if($H28="""", """", AVERAGE(split($H28, "";"")))"),288.1) -> 288.1 | J28: =IFERROR(__xludf.DUMMYFUNCTION("if(H28="""", """", SUM(split(H28, "";"")))"),576.2) -> 576.2
A29: 22 | B29: Heraclio Pianco | C29: Hilton Garden Inn Belo Horizonte Lourdes | D29: 46096 | E29: 46099 | F29: 46101 | G29: =if(OR(E29 = "", F29 = ""), "", IF(datedif(E29,F29,"D") = 0, 1, datedif(E29,F29,"D"))) -> 2 | H29: 646,38; 646,38 | I29: =IFERROR(__xludf.DUMMYFUNCTION("if($H29="""", """", AVERAGE(split($H29, "";"")))"),646.38) -> 646.38 | J29: =IFERROR(__xludf.DUMMYFUNCTION("if(H29="""", """", SUM(split(H29, "";"")))"),1292.76) -> 1292.76
A30: 22 | B30: Diego Regal | C30: Hilton Garden Inn Belo Horizonte Lourdes | D30: 46096 | E30: 46099 | F30: 46101 | G30: =if(OR(E30 = "", F30 = ""), "", IF(datedif(E30,F30,"D") = 0, 1, datedif(E30,F30,"D"))) -> 2 | H30: 646,38; 646,38 | I30: =IFERROR(__xludf.DUMMYFUNCTION("if($H30="""", """", AVERAGE(split($H30, "";"")))"),646.38) -> 646.38 | J30: =IFERROR(__xludf.DUMMYFUNCTION("if(H30="""", """", SUM(split(H30, "";"")))"),1292.76) -> 1292.76
A31: 22 | B31: Erik Anderson | C31: Hilton Garden Inn Belo Horizonte Lourdes | D31: 46096 | E31: 46099 | F31: 46101 | G31: =if(OR(E31 = "", F31 = ""), "", IF(datedif(E31,F31,"D") = 0, 1, datedif(E31,F31,"D"))) -> 2 | H31: 646,38; 646,38 | I31: =IFERROR(__xludf.DUMMYFUNCTION("if($H31="""", """", AVERAGE(split($H31, "";"")))"),646.38) -> 646.38 | J31: =IFERROR(__xludf.DUMMYFUNCTION("if(H31="""", """", SUM(split(H31, "";"")))"),1292.76) -> 1292.76
A32: 22 | B32: Helber Vieira | C32: Hilton Garden Inn Belo Horizonte Lourdes | D32: 46096 | E32: 46099 | F32: 46101 | G32: =if(OR(E32 = "", F32 = ""), "", IF(datedif(E32,F32,"D") = 0, 1, datedif(E32,F32,"D"))) -> 2 | H32: 646,38; 646,38 | I32: =IFERROR(__xludf.DUMMYFUNCTION("if($H32="""", """", AVERAGE(split($H32, "";"")))"),646.38) -> 646.38 | J32: =IFERROR(__xludf.DUMMYFUNCTION("if(H32="""", """", SUM(split(H32, "";"")))"),1292.76) -> 1292.76
A33: 22 | B33: Leandro Felix | C33: Hilton Garden Inn Belo Horizonte Lourdes | D33: 46097 | E33: 46100 | F33: 46101 | G33: =if(OR(E33 = "", F33 = ""), "", IF(datedif(E33,F33,"D") = 0, 1, datedif(E33,F33,"D"))) -> 1 | H33: 646.38 | I33: =IFERROR(__xludf.DUMMYFUNCTION("if($H33="""", """", AVERAGE(split($H33, "";"")))"),646.38) -> 646.38 | J33: =IFERROR(__xludf.DUMMYFUNCTION("if(H33="""", """", SUM(split(H33, "";"")))"),646.38) -> 646.38
A34: 22 | B34: Mikaella Pedrosa | C34: Hilton Garden Inn Belo Horizonte Lourdes | D34: 46097 | E34: 46100 | F34: 46101 | G34: =if(OR(E34 = "", F34 = ""), "", IF(datedif(E34,F34,"D") = 0, 1, datedif(E34,F34,"D"))) -> 1 | H34: 646.38 | I34: =IFERROR(__xludf.DUMMYFUNCTION("if($H34="""", """", AVERAGE(split($H34, "";"")))"),646.38) -> 646.38 | J34: =IFERROR(__xludf.DUMMYFUNCTION("if(H34="""", """", SUM(split(H34, "";"")))"),646.38) -> 646.38
A35: 24 | B35: Helber Vieira | E35: 46101 | F35: 46108 | G35: =if(OR(E35 = "", F35 = ""), "", IF(datedif(E35,F35,"D") = 0, 1, datedif(E35,F35,"D"))) -> 7 | I35: =IFERROR(__xludf.DUMMYFUNCTION("if($H35="""", """", AVERAGE(split($H35, "";"")))"),"") | J35: =IFERROR(__xludf.DUMMYFUNCTION("if(H35="""", """", SUM(split(H35, "";"")))"),"")
A36: 24 | B36: Roberta De Avila | E36: 46101 | F36: 46108 | G36: =if(OR(E36 = "", F36 = ""), "", IF(datedif(E36,F36,"D") = 0, 1, datedif(E36,F36,"D"))) -> 7 | I36: =IFERROR(__xludf.DUMMYFUNCTION("if($H36="""", """", AVERAGE(split($H36, "";"")))"),"") | J36: =IFERROR(__xludf.DUMMYFUNCTION("if(H36="""", """", SUM(split(H36, "";"")))"),"")
G37: =if(OR(E37 = "", F37 = ""), "", IF(datedif(E37,F37,"D") = 0, 1, datedif(E37,F37,"D"))) | I37: =IFERROR(__xludf.DUMMYFUNCTION("if($H37="""", """", AVERAGE(split($H37, "";"")))"),"") | J37: =IFERROR(__xludf.DUMMYFUNCTION("if(H37="""", """", SUM(split(H37, "";"")))"),"")
G38: =if(OR(E38 = "", F38 = ""), "", IF(datedif(E38,F38,"D") = 0, 1, datedif(E38,F38,"D"))) | I38: =IFERROR(__xludf.DUMMYFUNCTION("if($H38="""", """", AVERAGE(split($H38, "";"")))"),"") | J38: =IFERROR(__xludf.DUMMYFUNCTION("if(H38="""", """", SUM(split(H38, "";"")))"),"")
G39: =if(OR(E39 = "", F39 = ""), "", IF(datedif(E39,F39,"D") = 0, 1, datedif(E39,F39,"D"))) | I39: =IFERROR(__xludf.DUMMYFUNCTION("if($H39="""", """", AVERAGE(split($H39, "";"")))"),"") | J39: =IFERROR(__xludf.DUMMYFUNCTION("if(H39="""", """", SUM(split(H39, "";"")))"),"")
G40: =if(OR(E40 = "", F40 = ""), "", IF(datedif(E40,F40,"D") = 0, 1, datedif(E40,F40,"D"))) | I40: =IFERROR(__xludf.DUMMYFUNCTION("if($H40="""", """", AVERAGE(split($H40, "";"")))"),"") | J40: =IFERROR(__xludf.DUMMYFUNCTION("if(H40="""", """", SUM(split(H40, "";"")))"),"")
...

Sheet TRANSLADO
A1: ID da viagem (Interno) | B1: Nome do viajante | C1: Setor do viajante | D1: Motivo da viagem | E1: Empresa | F1: Origem | G1: Destino | H1: Quilometragem Estimada | I1: Data da viagem | J1: Valor (R$)
A2: 1 | B2: Vania Beneveli | C2: PEDAGÓGICO | D2: FORMAÇÃO | E2: Roberto | F2: Aeroporto | G2: Hotel | H2: 22 | I2: 46026 | J2: 100
A3: 1 | B3: Vania Beneveli | C3: PEDAGÓGICO | D3: FORMAÇÃO | E3: Roberto | F3: Hotel | G3: Aeroporto | H3: 22 | I3: 46029 | J3: 100
A4: 2 | B4: Simone Cortes | C4: PEDAGÓGICO | D4: FORMAÇÃO | E4: Roberto | F4: Aeroporto | G4: Hotel | H4: 21.2 | I4: 46029 | J4: 100
A5: 3 | B5: Alexandre Carvalho | C5: PEDAGÓGICO | D5: FORMAÇÃO | E5: Roberto | F5: Aeroporto | G5: Hotel | H5: 22 | I5: 46031 | J5: 100
A6: 3 | B6: Alexandre Carvalho | C6: PEDAGÓGICO | D6: FORMAÇÃO | E6: Roberto | F6: Hotel | G6: Aeroporto | H6: 22 | I6: 46036 | J6: 100
A7: 12 | B7: Vania Beneveli | C7: PEDAGÓGICO | D7: FORMAÇÃO | E7: Roberto | F7: Aeroporto | G7: Hotel | H7: 23 | I7: 46082 | J7: 100
A8: 12 | B8: Vania Beneveli | C8: PEDAGÓGICO | D8: FORMAÇÃO | E8: Roberto | F8: Hotel | G8: Aeroporto | H8: 23 | I8: 46085 | J8: 100
A9: 17 | B9: Alexandre Carvalho | C9: PEDAGÓGICO | D9: FORMAÇÃO | E9: Roberto | F9: Aeroporto | G9: Hotel | H9: 22 | I9: 46093 | J9: 100
A10: 17 | B10: Alexandre Carvalho | C10: PEDAGÓGICO | D10: FORMAÇÃO | E10: Roberto | F10: Estudo´play | G10: Aeroporto | H10: 15 | I10: 46095 | J10: 100
C11: Defina o setor... | D11: Defina o motivo...
C12: Defina o setor... | D12: Defina o motivo...
C13: Defina o setor... | D13: Defina o motivo...
C14: Defina o setor... | D14: Defina o motivo...
C15: Defina o setor... | D15: Defina o motivo...
C16: Defina o setor... | D16: Defina o motivo...
C17: Defina o setor... | D17: Defina o motivo...
C18: Defina o setor... | D18: Defina o motivo...
C19: Defina o setor... | D19: Defina o motivo...
C20: Defina o setor... | D20: Defina o motivo...
C21: Defina o setor... | D21: Defina o motivo...
C22: Defina o setor... | D22: Defina o motivo...
... C1999: Defina o setor... | D1999: Defina o motivo...

Sheet DADOS_POR_VIAGEM
A1: ID da viagem (Interno) | B1: Data da ida | C1: Data do retorno | D1: Duração | E1: Valor Total - Trechos Longos (R$) | F1: Valor Total - Trechos Curtos (R$) | G1: Valor Total Hospedagem (R$) | H1: Valor Total da Viagem (R$) | I1: Valor Total da Viagem (Pontos)
A2: =IFERROR(__xludf.DUMMYFUNCTION("UNIQUE(FLATTEN(UNIQUE(FILTER(TRECHOS_LONGOS!A2:A998, TRECHOS_LONGOS!A2:A998 <>"""")), UNIQUE(FILTER(TRANSLADO!A2:A998, TRANSLADO!A2:A998 <>""""))))"),1.0) -> 1 | B2: =IFERROR(__xludf.DUMMYFUNCTION("if(isna(MIN(FILTER(TRECHOS_LONGOS!$F:$F, TRECHOS_LONGOS!$A:$A = $A2))), ""Apenas translado"", MIN(FILTER(TRECHOS_LONGOS!$F:$F, TRECHOS_LONGOS!$A:$A = $A2)))"),46026.0) -> 46026 | C2: =IFERROR(__xludf.DUMMYFUNCTION("if(isna(max(FILTER(TRECHOS_LONGOS!$F:$F, TRECHOS_LONGOS!$A:$A = $A2))), ""Apenas translado"", MAX(FILTER(TRECHOS_LONGOS!$F:$F, TRECHOS_LONGOS!$A:$A = $A2)))"),46029.0) -> 46029 | D2: =if( B2 = "Apenas translado", 0, DATEDIF(B2,C2, "d")) -> 3 | E2: =SUMIF(TRECHOS_LONGOS!$A:$A, $A2, TRECHOS_LONGOS!Y:Y) -> 3989.72 | F2: =SUMIF(TRANSLADO!A:A, A2, TRANSLADO!J:J) -> 200 | G2: =SUMIF(HOSPEDAGEM!A:A, A2, HOSPEDAGEM!J:J) -> 1404.22 | H2: =if(or(E2 = "", F2 = "", G2 = ""), "", SUM(E2:G2)) -> 5593.94 | I2: =SUMIF(TRECHOS_LONGOS!$A:$A, $A2, TRECHOS_LONGOS!Z:Z) -> 0
A3: =IFERROR(__xludf.DUMMYFUNCTION("""COMPUTED_VALUE"""),2.0) -> 2 | B3: =IFERROR(__xludf.DUMMYFUNCTION("if(isna(MIN(FILTER(TRECHOS_LONGOS!$F:$F, TRECHOS_LONGOS!$A:$A = $A3))), ""Apenas translado"", MIN(FILTER(TRECHOS_LONGOS!$F:$F, TRECHOS_LONGOS!$A:$A = $A3)))"),46029.0) -> 46029 | C3: =IFERROR(__xludf.DUMMYFUNCTION("if(isna(max(FILTER(TRECHOS_LONGOS!$F:$F, TRECHOS_LONGOS!$A:$A = $A3))), ""Apenas translado"", MAX(FILTER(TRECHOS_LONGOS!$F:$F, TRECHOS_LONGOS!$A:$A = $A3)))"),46036.0) -> 46036 | D3: =if( B3 = "Apenas translado", 0, DATEDIF(B3,C3, "d")) -> 7 | E3: =SUMIF(TRECHOS_LONGOS!$A:$A, $A3, TRECHOS_LONGOS!Y:Y) -> 3156.76 | F3: =SUMIF(TRANSLADO!A:A, A3, TRANSLADO!J:J) -> 100 | G3: =SUMIF(HOSPEDAGEM!A:A, A3, HOSPEDAGEM!J:J) -> 1131.76 | H3: =if(or(E3 = "", F3 = "", G3 = ""), "", SUM(E3:G3)) -> 4388.52 | I3: =SUMIF(TRECHOS_LONGOS!$A:$A, $A3, TRECHOS_LONGOS!Z:Z) -> 0
A4: =IFERROR(__xludf.DUMMYFUNCTION("""COMPUTED_VALUE"""),3.0) -> 3 | B4: =IFERROR(__xludf.DUMMYFUNCTION("if(isna(MIN(FILTER(TRECHOS_LONGOS!$F:$F, TRECHOS_LONGOS!$A:$A = $A4))), ""Apenas translado"", MIN(FILTER(TRECHOS_LONGOS!$F:$F, TRECHOS_LONGOS!$A:$A = $A4)))"),46031.0) -> 46031 | C4: =IFERROR(__xludf.DUMMYFUNCTION("if(isna(max(FILTER(TRECHOS_LONGOS!$F:$F, TRECHOS_LONGOS!$A:$A = $A4))), ""Apenas translado"", MAX(FILTER(TRECHOS_LONGOS!$F:$F, TRECHOS_LONGOS!$A:$A = $A4)))"),46036.0) -> 46036 | D4: =if( B4 = "Apenas translado", 0, DATEDIF(B4,C4, "d")) -> 5 | E4: =SUMIF(TRECHOS_LONGOS!$A:$A, $A4, TRECHOS_LONGOS!Y:Y) -> 3156.76 | F4: =SUMIF(TRANSLADO!A:A, A4, TRANSLADO!J:J) -> 200 | G4: =SUMIF(HOSPEDAGEM!A:A, A4, HOSPEDAGEM!J:J) -> 1668.98 | H4: =if(or(E4 = "", F4 = "", G4 = ""), "", SUM(E4:G4)) -> 5025.74 | I4: =SUMIF(TRECHOS_LONGOS!$A:$A, $A4, TRECHOS_LONGOS!Z:Z) -> 0
A5: =IFERROR(__xludf.DUMMYFUNCTION("""COMPUTED_VALUE"""),4.0) -> 4 | B5: =IFERROR(__xludf.DUMMYFUNCTION("if(isna(MIN(FILTER(TRECHOS_LONGOS!$F:$F, TRECHOS_LONGOS!$A:$A = $A5))), ""Apenas translado"", MIN(FILTER(TRECHOS_LONGOS!$F:$F, TRECHOS_LONGOS!$A:$A = $A5)))"),46033.0) -> 46033 | C5: =IFERROR(__xludf.DUMMYFUNCTION("if(isna(max(FILTER(TRECHOS_LONGOS!$F:$F, TRECHOS_LONGOS!$A:$A = $A5))), ""Apenas translado"", MAX(FILTER(TRECHOS_LONGOS!$F:$F, TRECHOS_LONGOS!$A:$A = $A5)))"),46035.0) -> 46035 | D5: =if( B5 = "Apenas translado", 0, DATEDIF(B5,C5, "d")) -> 2 | E5: =SUMIF(TRECHOS_LONGOS!$A:$A, $A5, TRECHOS_LONGOS!Y:Y) -> 14356.82 | F5: =SUMIF(TRANSLADO!A:A, A5, TRANSLADO!J:J) -> 0 | G5: =SUMIF(HOSPEDAGEM!A:A, A5, HOSPEDAGEM!J:J) -> 2617.32 | H5: =if(or(E5 = "", F5 = "", G5 = ""), "", SUM(E5:G5)) -> 16974.14 | I5: =SUMIF(TRECHOS_LONGOS!$A:$A, $A5, TRECHOS_LONGOS!Z:Z) -> 0
A6: =IFERROR(__xludf.DUMMYFUNCTION("""COMPUTED_VALUE"""),5.0) -> 5 | B6: =IFERROR(__xludf.DUMMYFUNCTION("if(isna(MIN(FILTER(TRECHOS_LONGOS!$F:$F, TRECHOS_LONGOS!$A:$A = $A6))), ""Apenas translado"", MIN(FILTER(TRECHOS_LONGOS!$F:$F, TRECHOS_LONGOS!$A:$A = $A6)))"),46036.0) -> 46036 | C6: =IFERROR(__xludf.DUMMYFUNCTION("if(isna(max(FILTER(TRECHOS_LONGOS!$F:$F, TRECHOS_LONGOS!$A:$A = $A6))), ""Apenas translado"", MAX(FILTER(TRECHOS_LONGOS!$F:$F, TRECHOS_LONGOS!$A:$A = $A6)))"),46036.0) -> 46036 | D6: =if( B6 = "Apenas translado", 0, DATEDIF(B6,C6, "d")) -> 0 | E6: =SUMIF(TRECHOS_LONGOS!$A:$A, $A6, TRECHOS_LONGOS!Y:Y) -> 2610.77 | F6: =SUMIF(TRANSLADO!A:A, A6, TRANSLADO!J:J) -> 0 | G6: =SUMIF(HOSPEDAGEM!A:A, A6, HOSPEDAGEM!J:J) -> 0 | H6: =if(or(E6 = "", F6 = "", G6 = ""), "", SUM(E6:G6)) -> 2610.77 | I6: =SUMIF(TRECHOS_LONGOS!$A:$A, $A6, TRECHOS_LONGOS!Z:Z) -> 0
A7: =IFERROR(__xludf.DUMMYFUNCTION("""COMPUTED_VALUE"""),6.0) -> 6 | B7: =IFERROR(__xludf.DUMMYFUNCTION("if(isna(MIN(FILTER(TRECHOS_LONGOS!$F:$F, TRECHOS_LONGOS!$A:$A = $A7))), ""Apenas translado"", MIN(FILTER(TRECHOS_LONGOS!$F:$F, TRECHOS_LONGOS!$A:$A = $A7)))"),46037.0) -> 46037 | C7: =IFERROR(__xludf.DUMMYFUNCTION("if(isna(max(FILTER(TRECHOS_LONGOS!$F:$F, TRECHOS_LONGOS!$A:$A = $A7))), ""Apenas translado"", MAX(FILTER(TRECHOS_LONGOS!$F:$F, TRECHOS_LONGOS!$A:$A = $A7)))"),46038.0) -> 46038 | D7: =if( B7 = "Apenas translado", 0, DATEDIF(B7,C7, "d")) -> 1 | E7: =SUMIF(TRECHOS_LONGOS!$A:$A, $A7, TRECHOS_LONGOS!Y:Y) -> 12807.79 | F7: =SUMIF(TRANSLADO!A:A, A7, TRANSLADO!J:J) -> 0 | G7: =SUMIF(HOSPEDAGEM!A:A, A7, HOSPEDAGEM!J:J) -> 0 | H7: =if(or(E7 = "", F7 = "", G7 = ""), "", SUM(E7:G7)) -> 12807.79 | I7: =SUMIF(TRECHOS_LONGOS!$A:$A, $A7, TRECHOS_LONGOS!Z:Z) -> 0
A8: =IFERROR(__xludf.DUMMYFUNCTION("""COMPUTED_VALUE"""),7.0) -> 7 | B8: =IFERROR(__xludf.DUMMYFUNCTION("if(isna(MIN(FILTER(TRECHOS_LONGOS!$F:$F, TRECHOS_LONGOS!$A:$A = $A8))), ""Apenas translado"", MIN(FILTER(TRECHOS_LONGOS!$F:$F, TRECHOS_LONGOS!$A:$A = $A8)))"),46041.0) -> 46041 | C8: =IFERROR(__xludf.DUMMYFUNCTION("if(isna(max(FILTER(TRECHOS_LONGOS!$F:$F, TRECHOS_LONGOS!$A:$A = $A8))), ""Apenas translado"", MAX(FILTER(TRECHOS_LONGOS!$F:$F, TRECHOS_LONGOS!$A:$A = $A8)))"),46041.0) -> 46041 | D8: =if( B8 = "Apenas translado", 0, DATEDIF(B8,C8, "d")) -> 0 | E8: =SUMIF(TRECHOS_LONGOS!$A:$A, $A8, TRECHOS_LONGOS!Y:Y) -> 6277.36 | F8: =SUMIF(TRANSLADO!A:A, A8, TRANSLADO!J:J) -> 0 | G8: =SUMIF(HOSPEDAGEM!A:A, A8, HOSPEDAGEM!J:J) -> 456 | H8: =if(or(E8 = "", F8 = "", G8 = ""), "", SUM(E8:G8)) -> 6733.36 | I8: =SUMIF(TRECHOS_LONGOS!$A:$A, $A8, TRECHOS_LONGOS!Z:Z) -> 0
A9: =IFERROR(__xludf.DUMMYFUNCTION("""COMPUTED_VALUE"""),8.0) -> 8 | B9: =IFERROR(__xludf.DUMMYFUNCTION("if(isna(MIN(FILTER(TRECHOS_LONGOS!$F:$F, TRECHOS_LONGOS!$A:$A = $A9))), ""Apenas translado"", MIN(FILTER(TRECHOS_LONGOS!$F:$F, TRECHOS_LONGOS!$A:$A = $A9)))"),46046.0) -> 46046 | C9: =IFERROR(__xludf.DUMMYFUNCTION("if(isna(max(FILTER(TRECHOS_LONGOS!$F:$F, TRECHOS_LONGOS!$A:$A = $A9))), ""Apenas translado"", MAX(FILTER(TRECHOS_LONGOS!$F:$F, TRECHOS_LONGOS!$A:$A = $A9)))"),46046.0) -> 46046 | D9: =if( B9 = "Apenas translado", 0, DATEDIF(B9,C9, "d")) -> 0 | E9: =SUMIF(TRECHOS_LONGOS!$A:$A, $A9, TRECHOS_LONGOS!Y:Y) -> 1467.99 | F9: =SUMIF(TRANSLADO!A:A, A9, TRANSLADO!J:J) -> 0 | G9: =SUMIF(HOSPEDAGEM!A:A, A9, HOSPEDAGEM!J:J) -> 0 | H9: =if(or(E9 = "", F9 = "", G9 = ""), "", SUM(E9:G9)) -> 1467.99 | I9: =SUMIF(TRECHOS_LONGOS!$A:$A, $A9, TRECHOS_LONGOS!Z:Z) -> 0
A10: =IFERROR(__xludf.DUMMYFUNCTION("""COMPUTED_VALUE"""),9.0) -> 9 | B10: =IFERROR(__xludf.DUMMYFUNCTION("if(isna(MIN(FILTER(TRECHOS_LONGOS!$F:$F, TRECHOS_LONGOS!$A:$A = $A10))), ""Apenas translado"", MIN(FILTER(TRECHOS_LONGOS!$F:$F, TRECHOS_LONGOS!$A:$A = $A10)))"),46051.0) -> 46051 | C10: =IFERROR(__xludf.DUMMYFUNCTION("if(isna(max(FILTER(TRECHOS_LONGOS!$F:$F, TRECHOS_LONGOS!$A:$A = $A10))), ""Apenas translado"", MAX(FILTER(TRECHOS_LONGOS!$F:$F, TRECHOS_LONGOS!$A:$A = $A10)))"),46051.0) -> 46051 | D10: =if( B10 = "Apenas translado", 0, DATEDIF(B10,C10, "d")) -> 0 | E10: =SUMIF(TRECHOS_LONGOS!$A:$A, $A10, TRECHOS_LONGOS!Y:Y) -> 7319.28 | F10: =SUMIF(TRANSLADO!A:A, A10, TRANSLADO!J:J) -> 0 | G10: =SUMIF(HOSPEDAGEM!A:A, A10, HOSPEDAGEM!J:J) -> 0 | H10: =if(or(E10 = "", F10 = "", G10 = ""), "", SUM(E10:G10)) -> 7319.28 | I10: =SUMIF(TRECHOS_LONGOS!$A:$A, $A10, TRECHOS_LONGOS!Z:Z) -> 0
A11: =IFERROR(__xludf.DUMMYFUNCTION("""COMPUTED_VALUE"""),10.0) -> 10 | B11: =IFERROR(__xludf.DUMMYFUNCTION("if(isna(MIN(FILTER(TRECHOS_LONGOS!$F:$F, TRECHOS_LONGOS!$A:$A = $A11))), ""Apenas translado"", MIN(FILTER(TRECHOS_LONGOS!$F:$F, TRECHOS_LONGOS!$A:$A = $A11)))"),46072.0) -> 46072 | C11: =IFERROR(__xludf.DUMMYFUNCTION("if(isna(max(FILTER(TRECHOS_LONGOS!$F:$F, TRECHOS_LONGOS!$A:$A = $A11))), ""Apenas translado"", MAX(FILTER(TRECHOS_LONGOS!$F:$F, TRECHOS_LONGOS!$A:$A = $A11)))"),46073.0) -> 46073 | D11: =if( B11 = "Apenas translado", 0, DATEDIF(B11,C11, "d")) -> 1 | E11: =SUMIF(TRECHOS_LONGOS!$A:$A, $A11, TRECHOS_LONGOS!Y:Y) -> 9988.95 | F11: =SUMIF(TRANSLADO!A:A, A11, TRANSLADO!J:J) -> 0 | G11: =SUMIF(HOSPEDAGEM!A:A, A11, HOSPEDAGEM!J:J) -> 0 | H11: =if(or(E11 = "", F11 = "", G11 = ""), "", SUM(E11:G11)) -> 9988.95 | I11: =SUMIF(TRECHOS_LONGOS!$A:$A, $A11, TRECHOS_LONGOS!Z:Z) -> 0
